#VRML_SIM R2020a utf8
WorldInfo {
  info [
    "Thanks to Mehdi Ghanavati, Shahid Chamran University"
  ]
  title "Omni-wheels"
  basicTimeStep 8
}
Viewpoint {
  orientation 1 0 0 4.71238898038469
  position 0.0001231731438619889 8.92237093488225 5.834446268327524e-07
}
TexturedBackground {
}
TexturedBackgroundLight {
}
RectangleArena {
  floorSize 5 5
}
DEF OMNI_WHEELS Robot {
  translation 0 0.06 0
  children [
    DEF SOLID1 Solid {
      children [
        DEF WHEEL1 HingeJoint {
          jointParameters HingeJointParameters {
            axis 0 0 1
            anchor 0 0 0.1
          }
          device [
            RotationalMotor {
              name "wheel1"
            }
          ]
          endPoint Solid {
            translation 0 0 0.1
            rotation 0 0 1 0
            children [
              DEF sr1 HingeJoint {
                jointParameters HingeJointParameters {
                  anchor 0 0.05 0.02
                }
                endPoint Solid {
                  translation 0 0.05 0.02
                  rotation 1 0 0 0
                  children [
                    DEF r1 Transform {
                      rotation 0 0 1 1.5708
                      children [
                        DEF SMALL_WHEEL_SHAPE Shape {
                          appearance PBRAppearance {
                            baseColor 1 0.752941 0.796078
                            roughness 1
                            metalness 0
                          }
                          geometry Cylinder {
                            height 0.02
                            radius 0.01
                          }
                        }
                      ]
                    }
                  ]
                  name "sr1"
                  boundingObject USE r1
                  physics Physics {
                    density -1
                    mass 0.1
                  }
                }
              }
              DEF sr2 HingeJoint {
                jointParameters HingeJointParameters {
                  axis 0.707107 0.707107 0
                  anchor -0.03535 0.03535 0.02
                }
                endPoint Solid {
                  translation -0.03535 0.03535 0.02
                  rotation 0.7071067811865476 0.7071067811865476 0 0
                  children [
                    DEF r2 Transform {
                      rotation 0 0 1 2.27
                      children [
                        USE SMALL_WHEEL_SHAPE
                      ]
                    }
                  ]
                  name "sr2"
                  boundingObject USE r2
                  physics Physics {
                    density -1
                    mass 0.1
                  }
                }
              }
              DEF sr3 HingeJoint {
                jointParameters HingeJointParameters {
                  anchor 0 -0.05 0.02
                }
                endPoint Solid {
                  translation 0 -0.05 0.02
                  rotation 1 0 0 0
                  children [
                    DEF r3 Transform {
                      rotation 0 0 1 1.5708
                      children [
                        USE SMALL_WHEEL_SHAPE
                      ]
                    }
                  ]
                  name "sr3"
                  boundingObject USE r3
                  physics Physics {
                    density -1
                    mass 0.1
                  }
                }
              }
              DEF sr4 HingeJoint {
                jointParameters HingeJointParameters {
                  axis 0.707107 0.707107 0
                  anchor 0.03535 -0.03535 0.02
                }
                endPoint Solid {
                  translation 0.03535 -0.03535 0.02
                  rotation 0.7071067811865476 0.7071067811865476 0 0
                  children [
                    DEF r4 Transform {
                      rotation 0 0 1 2.27
                      children [
                        USE SMALL_WHEEL_SHAPE
                      ]
                    }
                  ]
                  name "sr4"
                  boundingObject USE r4
                  physics Physics {
                    density -1
                    mass 0.1
                  }
                }
              }
              DEF sr5 HingeJoint {
                jointParameters HingeJointParameters {
                  axis 0 1 0
                  anchor -0.05 0 0.02
                }
                endPoint Solid {
                  translation -0.05 0 0.02
                  children [
                    DEF r5 Transform {
                      children [
                        USE SMALL_WHEEL_SHAPE
                      ]
                    }
                  ]
                  name "sr5"
                  boundingObject USE r5
                  physics Physics {
                    density -1
                    mass 0.1
                  }
                }
              }
              DEF sr6 HingeJoint {
                jointParameters HingeJointParameters {
                  axis 0 1 0
                  anchor 0.05 0 0.02
                }
                endPoint Solid {
                  translation 0.05 0 0.02
                  children [
                    DEF r6 Transform {
                      children [
                        USE SMALL_WHEEL_SHAPE
                      ]
                    }
                  ]
                  name "sr6"
                  boundingObject USE r6
                  physics Physics {
                    density -1
                    mass 0.1
                  }
                }
              }
              DEF sr7 HingeJoint {
                jointParameters HingeJointParameters {
                  axis -0.707107 0.707107 0
                  anchor -0.03535 -0.03535 0.02
                }
                endPoint Solid {
                  translation -0.03535 -0.03535 0.02
                  rotation -0.7071067811865476 0.7071067811865476 0 0
                  children [
                    DEF r7 Transform {
                      rotation 0 0 1 0.76
                      children [
                        USE SMALL_WHEEL_SHAPE
                      ]
                    }
                  ]
                  name "sr7"
                  boundingObject USE r7
                  physics Physics {
                    density -1
                    mass 0.1
                  }
                }
              }
              DEF sr8 HingeJoint {
                jointParameters HingeJointParameters {
                  axis -0.707107 0.707107 0
                  anchor 0.03535 0.03535 0.02
                }
                endPoint Solid {
                  translation 0.03535 0.03535 0.02
                  rotation -0.7071067811865476 0.7071067811865476 0 0
                  children [
                    DEF r8 Transform {
                      rotation 0 0 1 0.76
                      children [
                        USE SMALL_WHEEL_SHAPE
                      ]
                    }
                  ]
                  name "sr8"
                  boundingObject USE r8
                  physics Physics {
                    density -1
                    mass 0.1
                  }
                }
              }
              DEF WHEEL_TRANS Transform {
                translation 0 0 0.02
                rotation 1 0 0 1.5708
                children [
                  DEF WHEEL_SHAPE Shape {
                    appearance PBRAppearance {
                      baseColor 0.678431 0.847059 0.901961
                      roughness 1
                      metalness 0
                    }
                    geometry Cylinder {
                      height 0.02
                      radius 0.05
                      subdivision 20
                    }
                  }
                ]
              }
            ]
            boundingObject Transform {
              translation 0 0 0.02
              rotation 1 0 0 1.5708
              children [
                DEF wheel1 Shape {
                  appearance PBRAppearance {
                    baseColor 0.8 0.8 0.8
                    transparency 0.12999999523162842
                    roughness 1
                    metalness 0
                    emissiveColor 0 1 0
                  }
                  geometry Cylinder {
                    height 0.02
                    radius 0.05
                  }
                }
              ]
            }
            physics Physics {
            }
          }
        }
      ]
      name "wheel1"
      boundingObject DEF DUMMY Sphere {
        radius 0.01
      }
      physics Physics {
      }
    }
    DEF SOLID2 Solid {
      rotation 0 1 0 2.09
      children [
        DEF WHEEL2 HingeJoint {
          jointParameters HingeJointParameters {
            axis 0 0 1
            anchor 0 0 0.1
          }
          device [
            RotationalMotor {
              name "wheel2"
            }
          ]
          endPoint Solid {
            translation 0 0 0.1
            rotation 0 0 1 0.00240580999995935
            children [
              DEF sr1 HingeJoint {
                jointParameters HingeJointParameters {
                  anchor 0 0.05 0.02
                }
                endPoint Solid {
                  translation 0 0.05 0.02
                  rotation 1 0 0 0
                  children [
                    USE r1
                  ]
                  name "sr1"
                  boundingObject USE r1
                  physics Physics {
                    density -1
                    mass 0.1
                  }
                }
              }
              DEF sr2 HingeJoint {
                jointParameters HingeJointParameters {
                  axis 0.707107 0.707107 0
                  anchor -0.03535 0.03535 0.02
                }
                endPoint Solid {
                  translation -0.03535 0.03535 0.02
                  rotation 0.7071067811865476 0.7071067811865476 0 0
                  children [
                    USE r2
                  ]
                  name "sr2"
                  boundingObject USE r2
                  physics Physics {
                    density -1
                    mass 0.1
                  }
                }
              }
              DEF sr3 HingeJoint {
                jointParameters HingeJointParameters {
                  anchor 0 -0.05 0.02
                }
                endPoint Solid {
                  translation 0 -0.05 0.02
                  rotation 1 0 0 0
                  children [
                    USE r3
                  ]
                  name "sr3"
                  boundingObject USE r3
                  physics Physics {
                    density -1
                    mass 0.1
                  }
                }
              }
              DEF sr4 HingeJoint {
                jointParameters HingeJointParameters {
                  axis 0.707107 0.707107 0
                  anchor 0.03535 -0.03535 0.02
                }
                endPoint Solid {
                  translation 0.03535 -0.03535 0.02
                  rotation 0.7071067811865476 0.7071067811865476 0 0
                  children [
                    USE r4
                  ]
                  name "sr4"
                  boundingObject USE r4
                  physics Physics {
                    density -1
                    mass 0.1
                  }
                }
              }
              DEF sr5 HingeJoint {
                jointParameters HingeJointParameters {
                  axis 0 1 0
                  anchor -0.05 0 0.02
                }
                endPoint Solid {
                  translation -0.05 0 0.02
                  children [
                    USE r5
                  ]
                  name "sr5"
                  boundingObject USE r5
                  physics Physics {
                    density -1
                    mass 0.1
                  }
                }
              }
              DEF sr6 HingeJoint {
                jointParameters HingeJointParameters {
                  axis 0 1 0
                  anchor 0.05 0 0.02
                }
                endPoint Solid {
                  translation 0.05 0 0.02
                  children [
                    USE r6
                  ]
                  name "sr6"
                  boundingObject USE r6
                  physics Physics {
                    density -1
                    mass 0.1
                  }
                }
              }
              DEF sr7 HingeJoint {
                jointParameters HingeJointParameters {
                  axis -0.707107 0.707107 0
                  anchor -0.03535 -0.03535 0.02
                }
                endPoint Solid {
                  translation -0.03535 -0.03535 0.02
                  rotation -0.7071067811865476 0.7071067811865476 0 0
                  children [
                    USE r7
                  ]
                  name "sr7"
                  boundingObject USE r7
                  physics Physics {
                    density -1
                    mass 0.1
                  }
                }
              }
              DEF sr8 HingeJoint {
                jointParameters HingeJointParameters {
                  axis -0.707107 0.707107 0
                  anchor 0.03535 0.03535 0.02
                }
                endPoint Solid {
                  translation 0.03535 0.03535 0.02
                  rotation -0.7071067811865476 0.7071067811865476 0 0
                  children [
                    USE r8
                  ]
                  name "sr8"
                  boundingObject USE r8
                  physics Physics {
                    density -1
                    mass 0.1
                  }
                }
              }
              USE WHEEL_TRANS
            ]
            boundingObject Transform {
              translation 0 0 0.02
              rotation 1 0 0 1.5708
              children [
                DEF wheel1 Shape {
                  appearance PBRAppearance {
                    baseColor 0.8 0.8 0.8
                    transparency 0.12999999523162842
                    roughness 1
                    metalness 0
                    emissiveColor 0 1 0
                  }
                  geometry Cylinder {
                    height 0.02
                    radius 0.05
                  }
                }
              ]
            }
            physics Physics {
            }
          }
        }
      ]
      name "wheel2"
      boundingObject USE DUMMY
      physics Physics {
      }
    }
    DEF SOLID3 Solid {
      rotation 0 1 0 4.18
      children [
        DEF WHEEL3 HingeJoint {
          jointParameters HingeJointParameters {
            axis 0 0 1
            anchor 0 0 0.1
          }
          device [
            RotationalMotor {
              name "wheel3"
            }
          ]
          endPoint Solid {
            translation 0 0 0.1
            rotation 0 0 1 0.0039094400000208316
            children [
              DEF sr1 HingeJoint {
                jointParameters HingeJointParameters {
                  anchor 0 0.05 0.02
                }
                endPoint Solid {
                  translation 0 0.05 0.02
                  rotation 1 0 0 0
                  children [
                    USE r1
                  ]
                  name "sr1"
                  boundingObject USE r1
                  physics Physics {
                    density -1
                    mass 0.1
                  }
                }
              }
              DEF sr2 HingeJoint {
                jointParameters HingeJointParameters {
                  axis 0.707107 0.707107 0
                  anchor -0.03535 0.03535 0.02
                }
                endPoint Solid {
                  translation -0.03535 0.03535 0.02
                  rotation 0.7071067811865476 0.7071067811865476 0 0
                  children [
                    USE r2
                  ]
                  name "sr2"
                  boundingObject USE r2
                  physics Physics {
                    density -1
                    mass 0.1
                  }
                }
              }
              DEF sr3 HingeJoint {
                jointParameters HingeJointParameters {
                  anchor 0 -0.05 0.02
                }
                endPoint Solid {
                  translation 0 -0.05 0.02
                  rotation 1 0 0 0
                  children [
                    USE r3
                  ]
                  name "sr3"
                  boundingObject USE r3
                  physics Physics {
                    density -1
                    mass 0.1
                  }
                }
              }
              DEF sr4 HingeJoint {
                jointParameters HingeJointParameters {
                  axis 0.707107 0.707107 0
                  anchor 0.03535 -0.03535 0.02
                }
                endPoint Solid {
                  translation 0.03535 -0.03535 0.02
                  rotation 0.7071067811865476 0.7071067811865476 0 0
                  children [
                    USE r4
                  ]
                  name "sr4"
                  boundingObject USE r4
                  physics Physics {
                    density -1
                    mass 0.1
                  }
                }
              }
              DEF sr5 HingeJoint {
                jointParameters HingeJointParameters {
                  axis 0 1 0
                  anchor -0.05 0 0.02
                }
                endPoint Solid {
                  translation -0.05 0 0.02
                  children [
                    USE r5
                  ]
                  name "sr5"
                  boundingObject USE r5
                  physics Physics {
                    density -1
                    mass 0.1
                  }
                }
              }
              DEF sr6 HingeJoint {
                jointParameters HingeJointParameters {
                  axis 0 1 0
                  anchor 0.05 0 0.02
                }
                endPoint Solid {
                  translation 0.05 0 0.02
                  children [
                    USE r6
                  ]
                  name "sr6"
                  boundingObject USE r6
                  physics Physics {
                    density -1
                    mass 0.1
                  }
                }
              }
              DEF sr7 HingeJoint {
                jointParameters HingeJointParameters {
                  axis -0.707107 0.707107 0
                  anchor -0.03535 -0.03535 0.02
                }
                endPoint Solid {
                  translation -0.03535 -0.03535 0.02
                  rotation -0.7071067811865476 0.7071067811865476 0 0
                  children [
                    USE r7
                  ]
                  name "sr7"
                  boundingObject USE r7
                  physics Physics {
                    density -1
                    mass 0.1
                  }
                }
              }
              DEF sr8 HingeJoint {
                jointParameters HingeJointParameters {
                  axis -0.707107 0.707107 0
                  anchor 0.03535 0.03535 0.02
                }
                endPoint Solid {
                  translation 0.03535 0.03535 0.02
                  rotation -0.7071067811865476 0.7071067811865476 0 0
                  children [
                    USE r8
                  ]
                  name "sr8"
                  boundingObject USE r8
                  physics Physics {
                    density -1
                    mass 0.1
                  }
                }
              }
              USE WHEEL_TRANS
            ]
            boundingObject Transform {
              translation 0 0 0.02
              rotation 1 0 0 1.5708
              children [
                DEF wheel1 Shape {
                  appearance PBRAppearance {
                    baseColor 0.8 0.8 0.8
                    transparency 0.12999999523162842
                    roughness 1
                    metalness 0
                    emissiveColor 0 1 0
                  }
                  geometry Cylinder {
                    height 0.02
                    radius 0.05
                  }
                }
              ]
            }
            physics Physics {
            }
          }
        }
      ]
      name "wheel2"
      boundingObject USE DUMMY
      physics Physics {
      }
    }
    DEF BODY_TRANS Transform {
      translation 0 0.03 0
      children [
        Shape {
          appearance PBRAppearance {
            baseColor 0.564706 0.933333 0.564706
            roughness 1
            metalness 0
          }
          geometry Cylinder {
            height 0.15
            radius 0.1
            subdivision 18
          }
        }
      ]
    }
    LED {
      translation 0 0.11 0
      children [
        Group {
          children [
            Shape {
              appearance PBRAppearance {
                baseColor 0.74902 0.74902 0.74902
                roughness 1
                metalness 0
              }
              geometry Box {
                size 0.1 0.01 0.1
              }
            }
            PointLight {
              attenuation 0 0 1
              color 1 0 0
              intensity 0.5
              location 0 0.03 0
              on FALSE
              castShadows TRUE
            }
          ]
        }
      ]
      color []
      gradual TRUE
    }
    DistanceSensor {
      translation 0 0.08 -0.1
      rotation 0 1 0 1.5708
      children [
        DEF SENSOR Transform {
          rotation 0 0 1 1.57
          children [
            Shape {
              appearance PBRAppearance {
                baseColor 0.975691 0.981481 0.0252992
                roughness 1
                metalness 0
              }
              geometry Cylinder {
                height 0.004
                radius 0.008
              }
            }
          ]
        }
      ]
      name "ds0"
      lookupTable [
        0 0 0
        1 1000 0
      ]
      type "generic"
      numberOfRays 2
      aperture 1
    }
    DistanceSensor {
      translation 0.0707108 0.08 -0.07071
      rotation 0 1 0 0.78539
      children [
        DEF SENSOR Transform {
          rotation 0 0 1 1.57
          children [
            Shape {
              appearance PBRAppearance {
                baseColor 0.975691 0.981481 0.0252992
                roughness 1
                metalness 0
              }
              geometry Cylinder {
                height 0.004
                radius 0.008
              }
            }
          ]
        }
      ]
      name "ds1"
      lookupTable [
        0 0 0
        1 1000 0
      ]
      type "generic"
      numberOfRays 2
      aperture 1
    }
    DistanceSensor {
      translation 0.1 0.08 -1.06144e-07
      rotation 0 1 0 5.307156870259904e-06
      children [
        DEF SENSOR Transform {
          rotation 0 0 1 1.57
          children [
            Shape {
              appearance PBRAppearance {
                baseColor 0.975691 0.981481 0.0252992
                roughness 1
                metalness 0
              }
              geometry Cylinder {
                height 0.004
                radius 0.008
              }
            }
          ]
        }
      ]
      name "ds2"
      lookupTable [
        0 0 0
        1 1000 0
      ]
      type "generic"
      numberOfRays 2
      aperture 1
    }
    DistanceSensor {
      translation 0.070711 0.08 0.0707101
      rotation 0 1 0 -0.785395307179586
      children [
        DEF SENSOR Transform {
          rotation 0 0 1 1.57
          children [
            Shape {
              appearance PBRAppearance {
                baseColor 0.975691 0.981481 0.0252992
                roughness 1
                metalness 0
              }
              geometry Cylinder {
                height 0.004
                radius 0.008
              }
            }
          ]
        }
      ]
      name "ds3"
      lookupTable [
        0 0 0
        1 1000 0
      ]
      type "generic"
      numberOfRays 2
      aperture 1
    }
    DistanceSensor {
      translation 6.3268e-07 0.08 0.1
      rotation 0 1 0 -1.57079
      children [
        DEF SENSOR Transform {
          rotation 0 0 1 1.57
          children [
            Shape {
              appearance PBRAppearance {
                baseColor 0.975691 0.981481 0.0252992
                roughness 1
                metalness 0
              }
              geometry Cylinder {
                height 0.004
                radius 0.008
              }
            }
          ]
        }
      ]
      name "ds4"
      lookupTable [
        0 0 0
        1 1000 0
      ]
      type "generic"
      numberOfRays 2
      aperture 1
    }
    DistanceSensor {
      translation -0.07071 0.08 0.0707113
      rotation 0 1 0 -2.356185307179586
      children [
        DEF SENSOR Transform {
          rotation 0 0 1 1.57
          children [
            Shape {
              appearance PBRAppearance {
                baseColor 0.975691 0.981481 0.0252992
                roughness 1
                metalness 0
              }
              geometry Cylinder {
                height 0.004
                radius 0.008
              }
            }
          ]
        }
      ]
      name "ds5"
      lookupTable [
        0 0 0
        1 1000 0
      ]
      type "generic"
      numberOfRays 2
      aperture 1
    }
    DistanceSensor {
      translation -0.1 0.08 -2.65359e-07
      rotation 0 1 0 3.14159
      children [
        DEF SENSOR Transform {
          rotation 0 0 1 1.57
          children [
            Shape {
              appearance PBRAppearance {
                baseColor 0.975691 0.981481 0.0252992
                roughness 1
                metalness 0
              }
              geometry Cylinder {
                height 0.004
                radius 0.008
              }
            }
          ]
        }
      ]
      name "ds6"
      lookupTable [
        0 0 0
        1 1000 0
      ]
      type "generic"
      numberOfRays 2
      aperture 1
    }
    DistanceSensor {
      translation -0.0707105 0.08 -0.070711
      rotation 0 1 0 2.35619
      children [
        DEF SENSOR Transform {
          rotation 0 0 1 1.57
          children [
            Shape {
              appearance PBRAppearance {
                baseColor 0.975691 0.981481 0.0252992
                roughness 1
                metalness 0
              }
              geometry Cylinder {
                height 0.004
                radius 0.008
              }
            }
          ]
        }
      ]
      name "ds7"
      lookupTable [
        0 0 0
        1 1000 0
      ]
      type "generic"
      numberOfRays 2
      aperture 1
    }
  ]
  boundingObject USE BODY_TRANS
  physics Physics {
  }
  controller "omni_wheel_controller"
}
SolidBox {
  translation -1.09731 0.2377375001039332 -1.15256
  rotation -0.3520310156358334 0.318649790868044 -0.8800775390896846 2.232199401272946e-18
  size 0.5 0.5 0.5
  physics Physics {
  }
}
SolidBox {
  translation 1.21269 0.2377375001039332 -1.15256
  rotation -0.3520310156358334 0.318649790868044 -0.8800775390896846 2.232199401272946e-18
  name "box(1)"
  size 0.5 0.5 0.5
  physics Physics {
  }
}
SolidBox {
  translation 0.62269 0.23773750000000007 0.06744
  rotation -0.7005929531808247 0.07054384850712524 0.7100655458414911 3.60049804085859e-18
  name "box(2)"
  size 0.5 0.5 0.5
  physics Physics {
  }
}
SolidBox {
  translation -1.02731 0.2377375001039332 1.14744
  rotation -0.3520310156358334 0.318649790868044 -0.8800775390896846 2.232199401272946e-18
  name "box(3)"
  size 0.5 0.5 0.5
  physics Physics {
  }
}
