#VRML_SIM R2020a utf8
WorldInfo {
  info [
    "Thanks to Mehdi Ghanavati, Shahid Chamran University"
  ]
  title "Omni-wheels"
  basicTimeStep 8
}
Viewpoint {
  orientation -0.440798002500895 0.8071121011704461 0.39276860507867595 1.6695619936231232
  position 4.278733546205725 3.1134051936234846 -2.0464973595493063
}
TexturedBackground {
}
TexturedBackgroundLight {
}
RectangleArena {
  translation 4.69286e-08 -0.01 0
  rotation 0 0 1 4.692820414042842e-06
  floorSize 5 5
}
DEF OMNI_WHEELS Robot {
  translation 2.22 0.07 -2
  children [
    VelodynePuck {
      translation 0 0.14 0
      version "Puck LITE"
    }
    DEF SOLID1 Solid {
      children [
        DEF WHEEL1 HingeJoint {
          jointParameters HingeJointParameters {
            axis 0 0 1
            anchor 0 0 0.1
          }
          device [
            RotationalMotor {
              name "wheel1"
            }
          ]
          endPoint Solid {
            translation 2.984293819639199e-10 6.974574268407362e-06 0.10000000000159216
            rotation -0.9993837962287866 4.3606089668371336e-05 -0.03510022697716095 1.3978528260658475e-07
            children [
              DEF sr1 HingeJoint {
                jointParameters HingeJointParameters {
                  anchor 0 0.05 0.02
                }
                endPoint Solid {
                  translation 0 0.05000000000000003 0.020000000000000018
                  rotation 1 0 0 0
                  children [
                    DEF r1 Transform {
                      rotation 0 0 1 1.5708
                      children [
                        DEF SMALL_WHEEL_SHAPE Shape {
                          appearance PBRAppearance {
                            baseColor 1 0.752941 0.796078
                            roughness 1
                            metalness 0
                          }
                          geometry Cylinder {
                            height 0.02
                            radius 0.01
                          }
                        }
                      ]
                    }
                  ]
                  name "sr1"
                  boundingObject USE r1
                  physics Physics {
                    density -1
                    mass 0.1
                  }
                }
              }
              DEF sr2 HingeJoint {
                jointParameters HingeJointParameters {
                  axis 0.707107 0.707107 0
                  anchor -0.03535 0.03535 0.02
                }
                endPoint Solid {
                  translation -0.03534999999999977 0.03534999999999998 0.020000000000000018
                  rotation 0.7071067811865476 0.7071067811865476 0 0
                  children [
                    DEF r2 Transform {
                      rotation 0 0 1 2.27
                      children [
                        USE SMALL_WHEEL_SHAPE
                      ]
                    }
                  ]
                  name "sr2"
                  boundingObject USE r2
                  physics Physics {
                    density -1
                    mass 0.1
                  }
                }
              }
              DEF sr3 HingeJoint {
                jointParameters HingeJointParameters {
                  anchor 0 -0.05 0.02
                }
                endPoint Solid {
                  translation 0 -0.05000000000000002 0.020000000000000018
                  rotation 1 0 0 0
                  children [
                    DEF r3 Transform {
                      rotation 0 0 1 1.5708
                      children [
                        USE SMALL_WHEEL_SHAPE
                      ]
                    }
                  ]
                  name "sr3"
                  boundingObject USE r3
                  physics Physics {
                    density -1
                    mass 0.1
                  }
                }
              }
              DEF sr4 HingeJoint {
                jointParameters HingeJointParameters {
                  axis 0.707107 0.707107 0
                  anchor 0.03535 -0.03535 0.02
                }
                endPoint Solid {
                  translation 0.035350000000000215 -0.03534999999999998 0.020000000000000018
                  rotation 0.7071067811865476 0.7071067811865476 0 0
                  children [
                    DEF r4 Transform {
                      rotation 0 0 1 2.27
                      children [
                        USE SMALL_WHEEL_SHAPE
                      ]
                    }
                  ]
                  name "sr4"
                  boundingObject USE r4
                  physics Physics {
                    density -1
                    mass 0.1
                  }
                }
              }
              DEF sr5 HingeJoint {
                jointParameters HingeJointParameters {
                  axis 0 1 0
                  anchor -0.05 0 0.02
                }
                endPoint Solid {
                  translation -0.050000000000000266 -2.7755575615628914e-17 0.020000000000000018
                  children [
                    DEF r5 Transform {
                      children [
                        USE SMALL_WHEEL_SHAPE
                      ]
                    }
                  ]
                  name "sr5"
                  boundingObject USE r5
                  physics Physics {
                    density -1
                    mass 0.1
                  }
                }
              }
              DEF sr6 HingeJoint {
                jointParameters HingeJointParameters {
                  axis 0 1 0
                  anchor 0.05 0 0.02
                }
                endPoint Solid {
                  translation 0.04999999999999982 0 0.020000000000000018
                  children [
                    DEF r6 Transform {
                      children [
                        USE SMALL_WHEEL_SHAPE
                      ]
                    }
                  ]
                  name "sr6"
                  boundingObject USE r6
                  physics Physics {
                    density -1
                    mass 0.1
                  }
                }
              }
              DEF sr7 HingeJoint {
                jointParameters HingeJointParameters {
                  axis -0.707107 0.707107 0
                  anchor -0.03535 -0.03535 0.02
                }
                endPoint Solid {
                  translation -0.03534999999999977 -0.03534999999999998 0.020000000000000018
                  rotation -0.7071067811865476 0.7071067811865476 0 0
                  children [
                    DEF r7 Transform {
                      rotation 0 0 1 0.76
                      children [
                        USE SMALL_WHEEL_SHAPE
                      ]
                    }
                  ]
                  name "sr7"
                  boundingObject USE r7
                  physics Physics {
                    density -1
                    mass 0.1
                  }
                }
              }
              DEF sr8 HingeJoint {
                jointParameters HingeJointParameters {
                  axis -0.707107 0.707107 0
                  anchor 0.03535 0.03535 0.02
                }
                endPoint Solid {
                  translation 0.035350000000000215 0.03534999999999999 0.020000000000000018
                  rotation -0.7071067811865476 0.7071067811865476 0 0
                  children [
                    DEF r8 Transform {
                      rotation 0 0 1 0.76
                      children [
                        USE SMALL_WHEEL_SHAPE
                      ]
                    }
                  ]
                  name "sr8"
                  boundingObject USE r8
                  physics Physics {
                    density -1
                    mass 0.1
                  }
                }
              }
              DEF WHEEL_TRANS Transform {
                translation 0 0 0.02
                rotation 1 0 0 1.5708
                children [
                  DEF WHEEL_SHAPE Shape {
                    appearance PBRAppearance {
                      baseColor 0.678431 0.847059 0.901961
                      roughness 1
                      metalness 0
                    }
                    geometry Cylinder {
                      height 0.02
                      radius 0.05
                      subdivision 20
                    }
                  }
                ]
              }
            ]
            boundingObject Transform {
              translation 0 0 0.02
              rotation 1 0 0 1.5708
              children [
                DEF wheel1 Shape {
                  appearance PBRAppearance {
                    baseColor 0.8 0.8 0.8
                    transparency 0.12999999523162842
                    roughness 1
                    metalness 0
                    emissiveColor 0 1 0
                  }
                  geometry Cylinder {
                    height 0.02
                    radius 0.05
                  }
                }
              ]
            }
            physics Physics {
            }
          }
        }
      ]
      name "wheel1"
      boundingObject DEF DUMMY Sphere {
        radius 0.01
      }
      physics Physics {
      }
    }
    DEF SOLID2 Solid {
      rotation 0 1 0 2.09
      children [
        DEF WHEEL2 HingeJoint {
          jointParameters HingeJointParameters {
            axis 0 0 1
            anchor 0 0 0.1
          }
          device [
            RotationalMotor {
              name "wheel2"
            }
          ]
          endPoint Solid {
            translation -2.551758804258952e-11 6.88612067097083e-06 0.1000000002180288
            rotation -5.725281167346877e-05 6.761295419053326e-08 0.9999999983610555 0.002405810004020338
            children [
              DEF sr1 HingeJoint {
                jointParameters HingeJointParameters {
                  anchor 0 0.05 0.02
                }
                endPoint Solid {
                  translation 0 0.05000000000000003 0.020000000000000018
                  rotation 1 0 0 0
                  children [
                    USE r1
                  ]
                  name "sr1"
                  boundingObject USE r1
                  physics Physics {
                    density -1
                    mass 0.1
                  }
                }
              }
              DEF sr2 HingeJoint {
                jointParameters HingeJointParameters {
                  axis 0.707107 0.707107 0
                  anchor -0.03535 0.03535 0.02
                }
                endPoint Solid {
                  translation -0.03534999999999977 0.035350000000000006 0.020000000000000018
                  rotation 0.7071067811865476 0.7071067811865476 0 0
                  children [
                    USE r2
                  ]
                  name "sr2"
                  boundingObject USE r2
                  physics Physics {
                    density -1
                    mass 0.1
                  }
                }
              }
              DEF sr3 HingeJoint {
                jointParameters HingeJointParameters {
                  anchor 0 -0.05 0.02
                }
                endPoint Solid {
                  translation 6.661338147750943e-16 -0.05000000000000001 0.020000000000000018
                  rotation 1 0 0 0
                  children [
                    USE r3
                  ]
                  name "sr3"
                  boundingObject USE r3
                  physics Physics {
                    density -1
                    mass 0.1
                  }
                }
              }
              DEF sr4 HingeJoint {
                jointParameters HingeJointParameters {
                  axis 0.707107 0.707107 0
                  anchor 0.03535 -0.03535 0.02
                }
                endPoint Solid {
                  translation 0.035350000000000215 -0.03535000000000001 0.020000000000000018
                  rotation 0.7071067811865476 0.7071067811865476 0 0
                  children [
                    USE r4
                  ]
                  name "sr4"
                  boundingObject USE r4
                  physics Physics {
                    density -1
                    mass 0.1
                  }
                }
              }
              DEF sr5 HingeJoint {
                jointParameters HingeJointParameters {
                  axis 0 1 0
                  anchor -0.05 0 0.02
                }
                endPoint Solid {
                  translation -0.04999999999999982 0 0.020000000000000018
                  children [
                    USE r5
                  ]
                  name "sr5"
                  boundingObject USE r5
                  physics Physics {
                    density -1
                    mass 0.1
                  }
                }
              }
              DEF sr6 HingeJoint {
                jointParameters HingeJointParameters {
                  axis 0 1 0
                  anchor 0.05 0 0.02
                }
                endPoint Solid {
                  translation 0.050000000000000044 -6.938893903907223e-17 0.020000000000000018
                  children [
                    USE r6
                  ]
                  name "sr6"
                  boundingObject USE r6
                  physics Physics {
                    density -1
                    mass 0.1
                  }
                }
              }
              DEF sr7 HingeJoint {
                jointParameters HingeJointParameters {
                  axis -0.707107 0.707107 0
                  anchor -0.03535 -0.03535 0.02
                }
                endPoint Solid {
                  translation -0.035350000000000215 -0.03535000000000003 0.020000000000000018
                  rotation -0.7071067811865476 0.7071067811865476 0 0
                  children [
                    USE r7
                  ]
                  name "sr7"
                  boundingObject USE r7
                  physics Physics {
                    density -1
                    mass 0.1
                  }
                }
              }
              DEF sr8 HingeJoint {
                jointParameters HingeJointParameters {
                  axis -0.707107 0.707107 0
                  anchor 0.03535 0.03535 0.02
                }
                endPoint Solid {
                  translation 0.03534999999999999 0.03534999999999999 0.020000000000000018
                  rotation -0.7071067811865476 0.7071067811865476 0 0
                  children [
                    USE r8
                  ]
                  name "sr8"
                  boundingObject USE r8
                  physics Physics {
                    density -1
                    mass 0.1
                  }
                }
              }
              USE WHEEL_TRANS
            ]
            boundingObject Transform {
              translation 0 0 0.02
              rotation 1 0 0 1.5708
              children [
                DEF wheel1 Shape {
                  appearance PBRAppearance {
                    baseColor 0.8 0.8 0.8
                    transparency 0.12999999523162842
                    roughness 1
                    metalness 0
                    emissiveColor 0 1 0
                  }
                  geometry Cylinder {
                    height 0.02
                    radius 0.05
                  }
                }
              ]
            }
            physics Physics {
            }
          }
        }
      ]
      name "wheel2"
      boundingObject USE DUMMY
      physics Physics {
      }
    }
    DEF SOLID3 Solid {
      rotation 0 1 0 4.18
      children [
        DEF WHEEL3 HingeJoint {
          jointParameters HingeJointParameters {
            axis 0 0 1
            anchor 0 0 0.1
          }
          device [
            RotationalMotor {
              name "wheel3"
            }
          ]
          endPoint Solid {
            translation -2.2253399123428605e-10 6.980787126409371e-06 0.09999999996041242
            rotation -3.5710983862914616e-05 6.775461903365931e-08 0.9999999993623606 0.003909440002406309
            children [
              DEF sr1 HingeJoint {
                jointParameters HingeJointParameters {
                  anchor 0 0.05 0.02
                }
                endPoint Solid {
                  translation 4.440892098500625e-16 0.04999999999999999 0.02000000000000024
                  rotation 1 0 0 0
                  children [
                    USE r1
                  ]
                  name "sr1"
                  boundingObject USE r1
                  physics Physics {
                    density -1
                    mass 0.1
                  }
                }
              }
              DEF sr2 HingeJoint {
                jointParameters HingeJointParameters {
                  axis 0.707107 0.707107 0
                  anchor -0.03535 0.03535 0.02
                }
                endPoint Solid {
                  translation -0.03534999999999977 0.035350000000000006 0.02000000000000024
                  rotation 0.7071067811865476 0.7071067811865476 0 0
                  children [
                    USE r2
                  ]
                  name "sr2"
                  boundingObject USE r2
                  physics Physics {
                    density -1
                    mass 0.1
                  }
                }
              }
              DEF sr3 HingeJoint {
                jointParameters HingeJointParameters {
                  anchor 0 -0.05 0.02
                }
                endPoint Solid {
                  translation 4.440892098500628e-16 -0.049999999999999954 0.020000000000000684
                  rotation 1 0 0 0
                  children [
                    USE r3
                  ]
                  name "sr3"
                  boundingObject USE r3
                  physics Physics {
                    density -1
                    mass 0.1
                  }
                }
              }
              DEF sr4 HingeJoint {
                jointParameters HingeJointParameters {
                  axis 0.707107 0.707107 0
                  anchor 0.03535 -0.03535 0.02
                }
                endPoint Solid {
                  translation 0.03534999999999977 -0.03534999999999996 0.020000000000000684
                  rotation 0.7071067811865476 0.7071067811865476 0 0
                  children [
                    USE r4
                  ]
                  name "sr4"
                  boundingObject USE r4
                  physics Physics {
                    density -1
                    mass 0.1
                  }
                }
              }
              DEF sr5 HingeJoint {
                jointParameters HingeJointParameters {
                  axis 0 1 0
                  anchor -0.05 0 0.02
                }
                endPoint Solid {
                  translation -0.050000000000000266 0 0.020000000000000462
                  children [
                    USE r5
                  ]
                  name "sr5"
                  boundingObject USE r5
                  physics Physics {
                    density -1
                    mass 0.1
                  }
                }
              }
              DEF sr6 HingeJoint {
                jointParameters HingeJointParameters {
                  axis 0 1 0
                  anchor 0.05 0 0.02
                }
                endPoint Solid {
                  translation 0.050000000000000266 2.77555756156289e-17 0.020000000000000906
                  children [
                    USE r6
                  ]
                  name "sr6"
                  boundingObject USE r6
                  physics Physics {
                    density -1
                    mass 0.1
                  }
                }
              }
              DEF sr7 HingeJoint {
                jointParameters HingeJointParameters {
                  axis -0.707107 0.707107 0
                  anchor -0.03535 -0.03535 0.02
                }
                endPoint Solid {
                  translation -0.03534999999999977 -0.035349999999999965 0.02000000000000024
                  rotation -0.7071067811865476 0.7071067811865476 0 0
                  children [
                    USE r7
                  ]
                  name "sr7"
                  boundingObject USE r7
                  physics Physics {
                    density -1
                    mass 0.1
                  }
                }
              }
              DEF sr8 HingeJoint {
                jointParameters HingeJointParameters {
                  axis -0.707107 0.707107 0
                  anchor 0.03535 0.03535 0.02
                }
                endPoint Solid {
                  translation 0.035350000000000215 0.035350000000000006 0.020000000000000684
                  rotation -0.7071067811865476 0.7071067811865476 0 0
                  children [
                    USE r8
                  ]
                  name "sr8"
                  boundingObject USE r8
                  physics Physics {
                    density -1
                    mass 0.1
                  }
                }
              }
              USE WHEEL_TRANS
            ]
            boundingObject Transform {
              translation 0 0 0.02
              rotation 1 0 0 1.5708
              children [
                DEF wheel1 Shape {
                  appearance PBRAppearance {
                    baseColor 0.8 0.8 0.8
                    transparency 0.12999999523162842
                    roughness 1
                    metalness 0
                    emissiveColor 0 1 0
                  }
                  geometry Cylinder {
                    height 0.02
                    radius 0.05
                  }
                }
              ]
            }
            physics Physics {
            }
          }
        }
      ]
      name "wheel2"
      boundingObject USE DUMMY
      physics Physics {
      }
    }
    DEF BODY_TRANS Transform {
      translation 0 0.03 0
      children [
        Shape {
          appearance PBRAppearance {
            baseColor 0.564706 0.933333 0.564706
            roughness 1
            metalness 0
          }
          geometry Cylinder {
            height 0.15
            radius 0.1
            subdivision 18
          }
        }
      ]
    }
    LED {
      translation 0 0.18 0
      children [
        Group {
          children [
            Shape {
              appearance PBRAppearance {
                baseColor 0.74902 0.74902 0.74902
                roughness 1
                metalness 0
              }
              geometry Box {
                size 0.1 0.01 0.1
              }
            }
            PointLight {
              attenuation 0 0 1
              color 0.4901960790157318 0.23137255012989044 0.16078431904315948
              intensity 0.5
              location 0 0.03 0
              on FALSE
              castShadows TRUE
            }
          ]
        }
      ]
      color []
      gradual TRUE
    }
    DistanceSensor {
      translation 0 0.08 -0.1
      rotation 0 1 0 1.5708
      children [
        DEF SENSOR Transform {
          rotation 0 0 1 1.57
          children [
            Shape {
              appearance PBRAppearance {
                baseColor 0.975691 0.981481 0.0252992
                roughness 1
                metalness 0
              }
              geometry Cylinder {
                height 0.004
                radius 0.008
              }
            }
          ]
        }
      ]
      name "ds0"
      lookupTable [
        0 0 0
        1 1000 0
      ]
      type "sonar"
      numberOfRays 27
      aperture 1
    }
    DistanceSensor {
      translation 0.0707108 0.08 -0.07071
      rotation 0 1 0 0.78539
      children [
        DEF SENSOR Transform {
          rotation 0 0 1 1.57
          children [
            Shape {
              appearance PBRAppearance {
                baseColor 0.975691 0.981481 0.0252992
                roughness 1
                metalness 0
              }
              geometry Cylinder {
                height 0.004
                radius 0.008
              }
            }
          ]
        }
      ]
      name "ds1"
      lookupTable [
        0 0 0
        1 1000 0
      ]
      type "sonar"
      numberOfRays 27
      aperture 1
    }
    DistanceSensor {
      translation 0.1 0.08 -1.06144e-07
      rotation 0 1 0 5.307156870259904e-06
      children [
        DEF SENSOR Transform {
          rotation 0 0 1 1.57
          children [
            Shape {
              appearance PBRAppearance {
                baseColor 0.975691 0.981481 0.0252992
                roughness 1
                metalness 0
              }
              geometry Cylinder {
                height 0.004
                radius 0.008
              }
            }
          ]
        }
      ]
      name "ds2"
      lookupTable [
        0 0 0
        1 1000 0
      ]
      type "sonar"
      numberOfRays 27
      aperture 1
    }
    DistanceSensor {
      translation 0.070711 0.08 0.0707101
      rotation 0 1 0 -0.785395307179586
      children [
        DEF SENSOR Transform {
          rotation 0 0 1 1.57
          children [
            Shape {
              appearance PBRAppearance {
                baseColor 0.975691 0.981481 0.0252992
                roughness 1
                metalness 0
              }
              geometry Cylinder {
                height 0.004
                radius 0.008
              }
            }
          ]
        }
      ]
      name "ds3"
      lookupTable [
        0 0 0
        1 1000 0
      ]
      type "sonar"
      numberOfRays 27
      aperture 1
    }
    DistanceSensor {
      translation 6.3268e-07 0.08 0.1
      rotation 0 1 0 -1.57079
      children [
        DEF SENSOR Transform {
          rotation 0 0 1 1.57
          children [
            Shape {
              appearance PBRAppearance {
                baseColor 0.975691 0.981481 0.0252992
                roughness 1
                metalness 0
              }
              geometry Cylinder {
                height 0.004
                radius 0.008
              }
            }
          ]
        }
      ]
      name "ds4"
      lookupTable [
        0 0 0
        1 1000 0
      ]
      type "sonar"
      numberOfRays 27
      aperture 1
    }
    DistanceSensor {
      translation -0.07071 0.08 0.0707113
      rotation 0 1 0 -2.356185307179586
      children [
        DEF SENSOR Transform {
          rotation 0 0 1 1.57
          children [
            Shape {
              appearance PBRAppearance {
                baseColor 0.975691 0.981481 0.0252992
                roughness 1
                metalness 0
              }
              geometry Cylinder {
                height 0.004
                radius 0.008
              }
            }
          ]
        }
      ]
      name "ds5"
      lookupTable [
        0 0 0
        1 1000 0
      ]
      type "sonar"
      numberOfRays 27
      aperture 1
    }
    DistanceSensor {
      translation -0.1 0.08 -2.65359e-07
      rotation 0 1 0 3.14159
      children [
        DEF SENSOR Transform {
          rotation 0 0 1 1.57
          children [
            Shape {
              appearance PBRAppearance {
                baseColor 0.975691 0.981481 0.0252992
                roughness 1
                metalness 0
              }
              geometry Cylinder {
                height 0.004
                radius 0.008
              }
            }
          ]
        }
      ]
      name "ds6"
      lookupTable [
        0 0 0
        1 1000 0
      ]
      type "sonar"
      numberOfRays 27
      aperture 1
    }
    DistanceSensor {
      translation -0.0707105 0.08 -0.070711
      rotation 0 1 0 2.35619
      children [
        DEF SENSOR Transform {
          rotation 0 0 1 1.57
          children [
            Shape {
              appearance PBRAppearance {
                baseColor 0.975691 0.981481 0.0252992
                roughness 1
                metalness 0
              }
              geometry Cylinder {
                height 0.004
                radius 0.008
              }
            }
          ]
        }
      ]
      name "ds7"
      lookupTable [
        0 0 0
        1 1000 0
      ]
      type "sonar"
      numberOfRays 27
      aperture 1
    }
  ]
  boundingObject USE BODY_TRANS
  physics Physics {
  }
  controller "omni_wheel_controller"
}
SolidBox {
  translation -1.09731 0.237738 -2.18256
  rotation -0.3520310156358334 0.318649790868044 -0.8800775390896846 2.232199401272946e-18
  size 0.5 0.5 0.5
  physics Physics {
  }
}
SolidBox {
  translation -0.38731 0.237738 -2.19256
  rotation -0.3520310156358334 0.318649790868044 -0.8800775390896846 2.232199401272946e-18
  name "box(1)"
  size 0.5 0.5 0.5
  physics Physics {
  }
}
SolidBox {
  translation 1.38269 0.237738 -2.01256
  rotation -0.7005929531808247 0.07054384850712524 0.7100655458414911 3.60049804085859e-18
  name "box(2)"
  size 0.5 0.5 0.5
  physics Physics {
  }
}
SolidBox {
  translation -2.21731 0.237738 -2.16256
  rotation -0.3520310156358334 0.318649790868044 -0.8800775390896846 2.232199401272946e-18
  name "box(3)"
  size 0.5 0.5 0.5
  physics Physics {
  }
}
